Workbook
Name Slicer_Manager: #N/A

Sheet Cover Page
C4: Data Analysis Start File
C9: Get 10% OFF our course using coupon code EMAIL10
C11: Get Our Excel for Business & Finance Course
C15: Made by Kenji Explains / Career Principles
C16: Note
C17: All content is copyright material of Kenji Explains / Career Principles
C18: This Excel model may not be reproduced or distributed by any means, including printing, screencapturing, or any other method without the prior permission of the publisher.

Sheet Breakdown
B2: Order ID | C2: Date | D2: Product | E2: Price | F2: Purchase Type | G2: Payment Method | H2: Manager | I2: Quantity | J2: City | K2: Country/region | L2: Revenue
B3: 10452 | C3: 44872 | D3: Fries | E3: 3.49 | F3: Online | G3: Gift Card | H3: Tom Jackson | I3: 574 | J3: #VALUE! | K3: {=_FV(Table2[[#This Row],[City]],"Country/region",TRUE)} -> #VALUE! | L3: =Table2[[#This Row],[Quantity]]*Table2[[#This Row],[Price]] -> 2003.26 | O3: First step is to convert this into a Table by highlighting the whole data set (select one cell) and using the shortcut ctrl + t | T3: Documentation done by Euan Garcia
B4: 10453 | C4: 44872 | D4: Beverages | E4: 2.95 | F4: Online | G4: Gift Card | H4: Pablo Perez | I4: 746 | J4: #VALUE! | K4: {=_FV(Table2[[#This Row],[City]],"Country/region",TRUE)} -> #VALUE! | L4: =Table2[[#This Row],[Quantity]]*Table2[[#This Row],[Price]] -> 2200.7
B5: 10454 | C5: 44872 | D5: Sides & Other | E5: 4.99 | F5: In-store | G5: Gift Card | H5: Joao Silva | I5: 201 | J5: #VALUE! | K5: {=_FV(Table2[[#This Row],[City]],"Country/region",TRUE)} -> #VALUE! | L5: =Table2[[#This Row],[Quantity]]*Table2[[#This Row],[Price]] -> 1002.99
B6: 10455 | C6: 44873 | D6: Burgers | E6: 12.99 | F6: In-store | G6: Credit Card | H6: Walter Muller | I6: 570 | J6: #VALUE! | K6: {=_FV(Table2[[#This Row],[City]],"Country/region",TRUE)} -> #VALUE! | L6: =Table2[[#This Row],[Quantity]]*Table2[[#This Row],[Price]] -> 7404.3
B7: 10456 | C7: 44873 | D7: Chicken Sandwiches | E7: 9.95 | F7: In-store | G7: Credit Card | H7: Walter Muller | I7: 202 | J7: #VALUE! | K7: {=_FV(Table2[[#This Row],[City]],"Country/region",TRUE)} -> #VALUE! | L7: =Table2[[#This Row],[Quantity]]*Table2[[#This Row],[Price]] -> 2009.9
B8: 10457 | C8: 44873 | D8: Fries | E8: 3.49 | F8: In-store | G8: Credit Card | H8: Remy Monet | I8: 574 | J8: #VALUE! | K8: {=_FV(Table2[[#This Row],[City]],"Country/region",TRUE)} -> #VALUE! | L8: =Table2[[#This Row],[Quantity]]*Table2[[#This Row],[Price]] -> 2003.26
B9: 10457 | C9: 44873 | D9: Fries | E9: 3.49 | F9: In-store | G9: Credit Card | H9: Remy Monet | I9: 574 | J9: #VALUE! | K9: {=_FV(Table2[[#This Row],[City]],"Country/region",TRUE)} -> #VALUE! | L9: =Table2[[#This Row],[Quantity]]*Table2[[#This Row],[Price]] -> 2003.26 | O9: We start by fixing the "Manager" column where the names are formatted incorrectly. We fix this by using "=TRIM()" Function We then format the text into a value. (This will be a repeated step) .. Highlight the column (Ctrl + Shift + ↓) .. Copy the column (Ctrl + C) .. Paste as value (Alt + H + VV)
B10: 10459 | C10: 44873 | D10: Sides & Other | E10: 4.99 | F10: In-store | G10: Credit Card | H10: Walter Muller | I10: 201 | J10: #VALUE! | K10: {=_FV(Table2[[#This Row],[City]],"Country/region",TRUE)} -> #VALUE! | L10: =Table2[[#This Row],[Quantity]]*Table2[[#This Row],[Price]] -> 1002.99
B11: 10460 | C11: 44874 | D11: Burgers | E11: 12.99 | F11: In-store | G11: Credit Card | H11: Remy Monet | I11: 555 | J11: #VALUE! | K11: {=_FV(Table2[[#This Row],[City]],"Country/region",TRUE)} -> #VALUE! | L11: =Table2[[#This Row],[Quantity]]*Table2[[#This Row],[Price]] -> 7209.45
B12: 10461 | C12: 44874 | D12: Chicken Sandwiches | E12: 9.95 | F12: In-store | G12: Credit Card | H12: Remy Monet | I12: 202 | J12: #VALUE! | K12: {=_FV(Table2[[#This Row],[City]],"Country/region",TRUE)} -> #VALUE! | L12: =Table2[[#This Row],[Quantity]]*Table2[[#This Row],[Price]] -> 2009.9
B13: 10462 | C13: 44874 | D13: Fries | E13: 3.49 | F13: In-store | G13: Credit Card | H13: Remy Monet | I13: 574 | J13: #VALUE! | K13: {=_FV(Table2[[#This Row],[City]],"Country/region",TRUE)} -> #VALUE! | L13: =Table2[[#This Row],[Quantity]]*Table2[[#This Row],[Price]] -> 2003.26
B14: 10463 | C14: 44874 | D14: Beverages | E14: 2.95 | F14: In-store | G14: Credit Card | H14: Remy Monet | I14: 678 | J14: #VALUE! | K14: {=_FV(Table2[[#This Row],[City]],"Country/region",TRUE)} -> #VALUE! | L14: =Table2[[#This Row],[Quantity]]*Table2[[#This Row],[Price]] -> 2000.1
B15: 10464 | C15: 44874 | D15: Sides & Other | E15: 4.99 | F15: In-store | G15: Credit Card | H15: Remy Monet | I15: 201 | J15: #VALUE! | K15: {=_FV(Table2[[#This Row],[City]],"Country/region",TRUE)} -> #VALUE! | L15: =Table2[[#This Row],[Quantity]]*Table2[[#This Row],[Price]] -> 1002.99
B16: 10465 | C16: 44875 | D16: Burgers | E16: 12.99 | F16: In-store | G16: Credit Card | H16: Pablo Perez | I16: 555 | J16: #VALUE! | K16: {=_FV(Table2[[#This Row],[City]],"Country/region",TRUE)} -> #VALUE! | L16: =Table2[[#This Row],[Quantity]]*Table2[[#This Row],[Price]] -> 7209.45
B17: 10466 | C17: 44875 | D17: Chicken Sandwiches | E17: 9.95 | F17: In-store | G17: Credit Card | H17: Pablo Perez | I17: 202 | J17: #VALUE! | K17: {=_FV(Table2[[#This Row],[City]],"Country/region",TRUE)} -> #VALUE! | L17: =Table2[[#This Row],[Quantity]]*Table2[[#This Row],[Price]] -> 2009.9
B18: 10467 | C18: 44875 | D18: Fries | E18: 3.49 | F18: In-store | G18: Credit Card | H18: Pablo Perez | I18: 574 | J18: #VALUE! | K18: {=_FV(Table2[[#This Row],[City]],"Country/region",TRUE)} -> #VALUE! | L18: =Table2[[#This Row],[Quantity]]*Table2[[#This Row],[Price]] -> 2003.26
B19: 10468 | C19: 44875 | D19: Beverages | E19: 2.95 | F19: In-store | G19: Credit Card | H19: Pablo Perez | I19: 678 | J19: #VALUE! | K19: {=_FV(Table2[[#This Row],[City]],"Country/region",TRUE)} -> #VALUE! | L19: =Table2[[#This Row],[Quantity]]*Table2[[#This Row],[Price]] -> 2000.1
B20: 10468 | C20: 44875 | D20: Beverages | E20: 2.95 | F20: In-store | G20: Credit Card | H20: Pablo Perez | I20: 678 | J20: #VALUE! | K20: {=_FV(Table2[[#This Row],[City]],"Country/region",TRUE)} -> #VALUE! | L20: =Table2[[#This Row],[Quantity]]*Table2[[#This Row],[Price]] -> 2000.1 | O20: We move onto rounding up the "Quantity" as the decimal places don't make sense in context of the items Use "=ROUNDUP()" Specifically =(ROUNDUP([@Quantity],0)) it sets the value to the closest whole number
B21: 10470 | C21: 44876 | D21: Burgers | E21: 12.99 | F21: In-store | G21: Credit Card | H21: Pablo Perez | I21: 555 | J21: #VALUE! | K21: {=_FV(Table2[[#This Row],[City]],"Country/region",TRUE)} -> #VALUE! | L21: =Table2[[#This Row],[Quantity]]*Table2[[#This Row],[Price]] -> 7209.45
B22: 10471 | C22: 44876 | D22: Chicken Sandwiches | E22: 9.95 | F22: In-store | G22: Credit Card | H22: Pablo Perez | I22: 202 | J22: #VALUE! | K22: {=_FV(Table2[[#This Row],[City]],"Country/region",TRUE)} -> #VALUE! | L22: =Table2[[#This Row],[Quantity]]*Table2[[#This Row],[Price]] -> 2009.9
B23: 10472 | C23: 44876 | D23: Fries | E23: 3.49 | F23: In-store | G23: Credit Card | H23: Pablo Perez | I23: 631 | J23: #VALUE! | K23: {=_FV(Table2[[#This Row],[City]],"Country/region",TRUE)} -> #VALUE! | L23: =Table2[[#This Row],[Quantity]]*Table2[[#This Row],[Price]] -> 2202.19
B24: 10473 | C24: 44876 | D24: Beverages | E24: 2.95 | F24: In-store | G24: Credit Card | H24: Pablo Perez | I24: 678 | J24: #VALUE! | K24: {=_FV(Table2[[#This Row],[City]],"Country/region",TRUE)} -> #VALUE! | L24: =Table2[[#This Row],[Quantity]]*Table2[[#This Row],[Price]] -> 2000.1
B25: 10474 | C25: 44876 | D25: Sides & Other | E25: 4.99 | F25: In-store | G25: Credit Card | H25: Pablo Perez | I25: 201 | J25: #VALUE! | K25: {=_FV(Table2[[#This Row],[City]],"Country/region",TRUE)} -> #VALUE! | L25: =Table2[[#This Row],[Quantity]]*Table2[[#This Row],[Price]] -> 1002.99
B26: 10475 | C26: 44877 | D26: Burgers | E26: 12.99 | F26: In-store | G26: Credit Card | H26: Pablo Perez | I26: 524 | J26: #VALUE! | K26: {=_FV(Table2[[#This Row],[City]],"Country/region",TRUE)} -> #VALUE! | L26: =Table2[[#This Row],[Quantity]]*Table2[[#This Row],[Price]] -> 6806.76
B27: 10476 | C27: 44877 | D27: Chicken Sandwiches | E27: 9.95 | F27: In-store | G27: Credit Card | H27: Pablo Perez | I27: 202 | J27: #VALUE! | K27: {=_FV(Table2[[#This Row],[City]],"Country/region",TRUE)} -> #VALUE! | L27: =Table2[[#This Row],[Quantity]]*Table2[[#This Row],[Price]] -> 2009.9
B28: 10477 | C28: 44877 | D28: Fries | E28: 3.49 | F28: In-store | G28: Credit Card | H28: Pablo Perez | I28: 631 | J28: #VALUE! | K28: {=_FV(Table2[[#This Row],[City]],"Country/region",TRUE)} -> #VALUE! | L28: =Table2[[#This Row],[Quantity]]*Table2[[#This Row],[Price]] -> 2202.19
B29: 10478 | C29: 44877 | D29: Beverages | E29: 2.95 | F29: In-store | G29: Credit Card | H29: Pablo Perez | I29: 678 | J29: #VALUE! | K29: {=_FV(Table2[[#This Row],[City]],"Country/region",TRUE)} -> #VALUE! | L29: =Table2[[#This Row],[Quantity]]*Table2[[#This Row],[Price]] -> 2000.1 | O29: We can grab the country of the city by highlighting the column then going into the Data tab and selecting Geography
B30: 10479 | C30: 44877 | D30: Sides & Other | E30: 4.99 | F30: In-store | G30: Credit Card | H30: Pablo Perez | I30: 201 | J30: #VALUE! | K30: {=_FV(Table2[[#This Row],[City]],"Country/region",TRUE)} -> #VALUE! | L30: =Table2[[#This Row],[Quantity]]*Table2[[#This Row],[Price]] -> 1002.99
B31: 10480 | C31: 44878 | D31: Burgers | E31: 12.99 | F31: In-store | G31: Credit Card | H31: Pablo Perez | I31: 509 | J31: #VALUE! | K31: {=_FV(Table2[[#This Row],[City]],"Country/region",TRUE)} -> #VALUE! | L31: =Table2[[#This Row],[Quantity]]*Table2[[#This Row],[Price]] -> 6611.91
B32: 10481 | C32: 44878 | D32: Chicken Sandwiches | E32: 9.95 | F32: In-store | G32: Credit Card | H32: Pablo Perez | I32: 202 | J32: #VALUE! | K32: {=_FV(Table2[[#This Row],[City]],"Country/region",TRUE)} -> #VALUE! | L32: =Table2[[#This Row],[Quantity]]*Table2[[#This Row],[Price]] -> 2009.9
B33: 10482 | C33: 44878 | D33: Fries | E33: 25.5 | F33: In-store | G33: Credit Card | H33: Joao Silva | I33: 631 | J33: #VALUE! | K33: {=_FV(Table2[[#This Row],[City]],"Country/region",TRUE)} -> #VALUE! | L33: =Table2[[#This Row],[Quantity]]*Table2[[#This Row],[Price]] -> 16090.5 | O33: We can remove duplicate data sets by going into Data and selecting Remove Duplicates
B34: 10483 | C34: 44878 | D34: Beverages | E34: 33.22 | F34: In-store | G34: Credit Card | H34: Joao Silva | I34: 678 | J34: #VALUE! | K34: {=_FV(Table2[[#This Row],[City]],"Country/region",TRUE)} -> #VALUE! | L34: =Table2[[#This Row],[Quantity]]*Table2[[#This Row],[Price]] -> 22523.16
B35: 10484 | C35: 44878 | D35: Sides & Other | E35: 21.44 | F35: In-store | G35: Credit Card | H35: Joao Silva | I35: 201 | J35: #VALUE! | K35: {=_FV(Table2[[#This Row],[City]],"Country/region",TRUE)} -> #VALUE! | L35: =Table2[[#This Row],[Quantity]]*Table2[[#This Row],[Price]] -> 4309.44
B36: 10485 | C36: 44879 | D36: Burgers | E36: 27.99 | F36: In-store | G36: Credit Card | H36: Joao Silva | I36: 524 | J36: #VALUE! | K36: {=_FV(Table2[[#This Row],[City]],"Country/region",TRUE)} -> #VALUE! | L36: =Table2[[#This Row],[Quantity]]*Table2[[#This Row],[Price]] -> 14666.76
B37: 10486 | C37: 44879 | D37: Chicken Sandwiches | E37: 29.05 | F37: In-store | G37: Credit Card | H37: Joao Silva | I37: 202 | J37: #VALUE! | K37: {=_FV(Table2[[#This Row],[City]],"Country/region",TRUE)} -> #VALUE! | L37: =Table2[[#This Row],[Quantity]]*Table2[[#This Row],[Price]] -> 5868.1
B38: 10487 | C38: 44879 | D38: Fries | E38: 3.49 | F38: In-store | G38: Credit Card | H38: Joao Silva | I38: 631 | J38: #VALUE! | K38: {=_FV(Table2[[#This Row],[City]],"Country/region",TRUE)} -> #VALUE! | L38: =Table2[[#This Row],[Quantity]]*Table2[[#This Row],[Price]] -> 2202.19
B39: 10488 | C39: 44879 | D39: Beverages | E39: 2.95 | F39: In-store | G39: Credit Card | H39: Joao Silva | I39: 678 | J39: #VALUE! | K39: {=_FV(Table2[[#This Row],[City]],"Country/region",TRUE)} -> #VALUE! | L39: =Table2[[#This Row],[Quantity]]*Table2[[#This Row],[Price]] -> 2000.1 | O39: Price | R39: I was able to create this whole table by using the Excel add-in "Data Analysis" I used Descriptive Statistics on the price column and selected the summary statistics to produce a table with all the necessary information
B40: 10489 | C40: 44879 | D40: Sides & Other | E40: 4.99 | F40: In-store | G40: Credit Card | H40: Pablo Perez | I40: 201 | J40: #VALUE! | K40: {=_FV(Table2[[#This Row],[City]],"Country/region",TRUE)} -> #VALUE! | L40: =Table2[[#This Row],[Quantity]]*Table2[[#This Row],[Price]] -> 1002.99
B41: 10490 | C41: 44880 | D41: Burgers | E41: 12.99 | F41: In-store | G41: Credit Card | H41: Pablo Perez | I41: 509 | J41: #VALUE! | K41: {=_FV(Table2[[#This Row],[City]],"Country/region",TRUE)} -> #VALUE! | L41: =Table2[[#This Row],[Quantity]]*Table2[[#This Row],[Price]] -> 6611.91 | O41: Mean | P41: 7.2691221
...

Sheet Clean
B2: Order ID | C2: Date | D2: Product | E2: Price | F2: Quantity | G2: Cost | H2: City | I2: Country | J2: Purchase Type | K2: Payment Method | L2: Manager | M2: Revenue
B3: 10452 | C3: 44872 | D3: Fries | E3: 3.49 | F3: 574 | G3: 0.88 | H3: #VALUE! | I3: {=_FV(H3,"Country/region",TRUE)} -> #VALUE! | J3: Online | K3: Gift Card | L3: Tom Jackson | M3: =Table1[[#This Row],[Price]]*Table1[[#This Row],[Quantity]] -> 2003.26
B4: 10453 | C4: 44872 | D4: Beverages | E4: 2.95 | F4: 746 | G4: 0.47 | H4: #VALUE! | I4: {=_FV(H4,"Country/region",TRUE)} -> #VALUE! | J4: Online | K4: Gift Card | L4: Pablo Perez | M4: =Table1[[#This Row],[Price]]*Table1[[#This Row],[Quantity]] -> 2200.7
B5: 10454 | C5: 44872 | D5: Sides & Other | E5: 4.99 | F5: 201 | G5: 2.25 | H5: #VALUE! | I5: {=_FV(H5,"Country/region",TRUE)} -> #VALUE! | J5: In-store | K5: Gift Card | L5: Joao Silva | M5: =Table1[[#This Row],[Price]]*Table1[[#This Row],[Quantity]] -> 1002.99
B6: 10455 | C6: 44873 | D6: Burgers | E6: 12.99 | F6: 570 | G6: 4.32 | H6: #VALUE! | I6: {=_FV(H6,"Country/region",TRUE)} -> #VALUE! | J6: In-store | K6: Credit Card | L6: Walter Muller | M6: =Table1[[#This Row],[Price]]*Table1[[#This Row],[Quantity]] -> 7404.3
B7: 10456 | C7: 44873 | D7: Chicken Sandwiches | E7: 9.95 | F7: 202 | G7: 2.85 | H7: #VALUE! | I7: {=_FV(H7,"Country/region",TRUE)} -> #VALUE! | J7: In-store | K7: Credit Card | L7: Walter Muller | M7: =Table1[[#This Row],[Price]]*Table1[[#This Row],[Quantity]] -> 2009.9
B8: 10457 | C8: 44873 | D8: Fries | E8: 3.49 | F8: 574 | G8: 0.88 | H8: #VALUE! | I8: {=_FV(H8,"Country/region",TRUE)} -> #VALUE! | J8: In-store | K8: Credit Card | L8: Remy Monet | M8: =Table1[[#This Row],[Price]]*Table1[[#This Row],[Quantity]] -> 2003.26
B9: 10459 | C9: 44873 | D9: Sides & Other | E9: 4.99 | F9: 201 | G9: 2.25 | H9: #VALUE! | I9: {=_FV(H9,"Country/region",TRUE)} -> #VALUE! | J9: In-store | K9: Credit Card | L9: Remy Monet | M9: =Table1[[#This Row],[Price]]*Table1[[#This Row],[Quantity]] -> 1002.99
B10: 10460 | C10: 44874 | D10: Burgers | E10: 12.99 | F10: 555 | G10: 4.32 | H10: #VALUE! | I10: {=_FV(H10,"Country/region",TRUE)} -> #VALUE! | J10: In-store | K10: Credit Card | L10: Walter Muller | M10: =Table1[[#This Row],[Price]]*Table1[[#This Row],[Quantity]] -> 7209.45
B11: 10461 | C11: 44874 | D11: Chicken Sandwiches | E11: 9.95 | F11: 202 | G11: 2.85 | H11: #VALUE! | I11: {=_FV(H11,"Country/region",TRUE)} -> #VALUE! | J11: In-store | K11: Credit Card | L11: Remy Monet | M11: =Table1[[#This Row],[Price]]*Table1[[#This Row],[Quantity]] -> 2009.9
B12: 10462 | C12: 44874 | D12: Fries | E12: 3.49 | F12: 574 | G12: 0.88 | H12: #VALUE! | I12: {=_FV(H12,"Country/region",TRUE)} -> #VALUE! | J12: In-store | K12: Credit Card | L12: Remy Monet | M12: =Table1[[#This Row],[Price]]*Table1[[#This Row],[Quantity]] -> 2003.26
B13: 10463 | C13: 44874 | D13: Beverages | E13: 2.95 | F13: 678 | G13: 0.47 | H13: #VALUE! | I13: {=_FV(H13,"Country/region",TRUE)} -> #VALUE! | J13: In-store | K13: Credit Card | L13: Remy Monet | M13: =Table1[[#This Row],[Price]]*Table1[[#This Row],[Quantity]] -> 2000.1
B14: 10464 | C14: 44874 | D14: Sides & Other | E14: 4.99 | F14: 201 | G14: 2.25 | H14: #VALUE! | I14: {=_FV(H14,"Country/region",TRUE)} -> #VALUE! | J14: In-store | K14: Credit Card | L14: Remy Monet | M14: =Table1[[#This Row],[Price]]*Table1[[#This Row],[Quantity]] -> 1002.99
... B256: 10713 | C256: 44924 | D256: Beverages | E256: 2.95 | F256: 678 | G256: 0.47 | H256: #VALUE! | I256: {=_FV(H256,"Country/region",TRUE)} -> #VALUE! | J256: Drive-thru | K256: Gift Card | L256: Walter Muller | M256: =Table1[[#This Row],[Price]]*Table1[[#This Row],[Quantity]] -> 2000.1

Sheet Detail1
A1: Details for Sum of Revenue
A3: Order ID | B3: Date | C3: Product | D3: Price | E3: Purchase Type | F3: Payment Method | G3: Manager | H3: Quantity | I3: City | J3: Country/region | K3: Revenue
A4: 10452 | B4: 44872 | C4: Fries | D4: 3.49 | E4: Online | F4: Gift Card | G4: Tom Jackson | H4: 574 | I4: #VALUE! | J4: #VALUE! | K4: 2003.26
A5: 10453 | B5: 44872 | C5: Beverages | D5: 2.95 | E5: Online | F5: Gift Card | G5: Pablo Perez | H5: 746 | I5: #VALUE! | J5: #VALUE! | K5: 2200.7
A6: 10454 | B6: 44872 | C6: Sides & Other | D6: 4.99 | E6: In-store | F6: Gift Card | G6: Joao Silva | H6: 201 | I6: #VALUE! | J6: #VALUE! | K6: 1002.99
A7: 10455 | B7: 44873 | C7: Burgers | D7: 12.99 | E7: In-store | F7: Credit Card | G7: Walter Muller | H7: 570 | I7: #VALUE! | J7: #VALUE! | K7: 7404.3
A8: 10456 | B8: 44873 | C8: Chicken Sandwiches | D8: 9.95 | E8: In-store | F8: Credit Card | G8: Walter Muller | H8: 202 | I8: #VALUE! | J8: #VALUE! | K8: 2009.9
A9: 10457 | B9: 44873 | C9: Fries | D9: 3.49 | E9: In-store | F9: Credit Card | G9: Remy Monet | H9: 574 | I9: #VALUE! | J9: #VALUE! | K9: 2003.26
A10: 10457 | B10: 44873 | C10: Fries | D10: 3.49 | E10: In-store | F10: Credit Card | G10: Remy Monet | H10: 574 | I10: #VALUE! | J10: #VALUE! | K10: 2003.26
A11: 10459 | B11: 44873 | C11: Sides & Other | D11: 4.99 | E11: In-store | F11: Credit Card | G11: Walter Muller | H11: 201 | I11: #VALUE! | J11: #VALUE! | K11: 1002.99
A12: 10460 | B12: 44874 | C12: Burgers | D12: 12.99 | E12: In-store | F12: Credit Card | G12: Remy Monet | H12: 555 | I12: #VALUE! | J12: #VALUE! | K12: 7209.45
A13: 10461 | B13: 44874 | C13: Chicken Sandwiches | D13: 9.95 | E13: In-store | F13: Credit Card | G13: Remy Monet | H13: 202 | I13: #VALUE! | J13: #VALUE! | K13: 2009.9
A14: 10462 | B14: 44874 | C14: Fries | D14: 3.49 | E14: In-store | F14: Credit Card | G14: Remy Monet | H14: 574 | I14: #VALUE! | J14: #VALUE! | K14: 2003.26
A15: 10463 | B15: 44874 | C15: Beverages | D15: 2.95 | E15: In-store | F15: Credit Card | G15: Remy Monet | H15: 678 | I15: #VALUE! | J15: #VALUE! | K15: 2000.1
... A265: 10713 | B265: 44924 | C265: Beverages | D265: 2.95 | E265: Drive-thru | F265: Gift Card | G265: Walter Muller | H265: 678 | I265: #VALUE! | J265: #VALUE! | K265: 2000.1

Sheet Analysis
B2: Data Analysis Questions
H3: Best Selling Product PivotTable | K3: Total Revenue | M3: Revenue by Payment Method
B4: 1) What is our best selling product? | H4: Product | I4: Sum of Quantity | K4: Sum of Revenue | M4: Payment Method | N4: Sum of Revenue
B5: Beverages | H5: Beverages | I5: 37090 | K5: 821544.37 | M5: Credit Card | N5: 0.50298207
B6: 2) What is our total revenue? | H6: Fries | I6: 33272 | M6: Cash | N6: 0.291517
B7: 821544.37 | H7: Burgers | I7: 29572 | M7: Gift Card | N7: 0.20550093
B8: 3) What is the revenue breakdown by payment method? | H8: Chicken Sandwiches | I8: 11184 | M8: Grand Total | N8: 1
B9: Credit Card | H9: Sides & Other | I9: 10251
H10: Grand Total | I10: 121369
H13: These PivotTable examples are to show how to solve each question using the information created and cleaned in the breakdown sheet

Sheet Manager Revenue
A3: Row Labels | B3: Sum of Revenue
A4: Remy Monet | B4: 81931.16
A5: Walter Muller | B5: 100698.95
A6: Pablo Perez | B6: 143836.02
A7: Tom Jackson | B7: 211522.88
A8: Joao Silva | B8: 283555.36
A9: Grand Total | B9: 821544.37

Sheet Most Profit from Product
A3: Row Labels | B3: Sum of Revenue
A4: Burgers | B4: 123561.93
A5: Beverages | B5: 56129.56
A6: Fries | B6: 47716.88
A7: Chicken Sandwiches | B7: 36792.7
A8: Sides & Other | B8: 19354.29
A9: Grand Total | B9: 283555.36

Sheet Sales by Week-Month
A3: Row Labels | B3: Sum of Revenue
A4: Nov | B4: 98708.14
A5: 07-Nov | B5: 1002.99
A6: 13-Nov | B6: 45926.19
A7: 14-Nov | B7: 31543.91
A8: 19-Nov | B8: 7414.11
A9: 20-Nov | B9: 8219.12
A10: 23-Nov | B10: 4601.82
A11: Dec | B11: 184847.22
A12: 12-Dec | B12: 3003.09
A13: 13-Dec | B13: 14619.48
A14: 14-Dec | B14: 14623.63
A15: 15-Dec | B15: 14415.79
... A25: Grand Total | B25: 283555.36

Sheet Sales By Payment Method
A3: Row Labels | B3: Sum of Revenue2 | C3: Sum of Revenue
A4: Gift Card | B4: 1 | C4: 0.24088467
A5: Credit Card | B5: 1 | C5: 0.2887659
A6: Cash | B6: 1 | C6: 0.47034942
A7: Grand Total | B7: 1 | C7: 1

Sheet Detail2
A1: Details for Sum of Revenue2 - Payment Method: Gift Card
A3: Order ID | B3: Date | C3: Product | D3: Price | E3: Purchase Type | F3: Payment Method | G3: Manager | H3: Quantity | I3: City | J3: Country/region | K3: Revenue
A4: 10452 | B4: 44872 | C4: Fries | D4: 3.49 | E4: Online | F4: Gift Card | G4: Tom Jackson | H4: 574 | I4: #VALUE! | J4: #VALUE! | K4: 2003.26
A5: 10453 | B5: 44872 | C5: Beverages | D5: 2.95 | E5: Online | F5: Gift Card | G5: Pablo Perez | H5: 746 | I5: #VALUE! | J5: #VALUE! | K5: 2200.7
A6: 10454 | B6: 44872 | C6: Sides & Other | D6: 4.99 | E6: In-store | F6: Gift Card | G6: Joao Silva | H6: 201 | I6: #VALUE! | J6: #VALUE! | K6: 1002.99
A7: 10713 | B7: 44924 | C7: Beverages | D7: 2.95 | E7: Drive-thru | F7: Gift Card | G7: Walter Muller | H7: 678 | I7: #VALUE! | J7: #VALUE! | K7: 2000.1
A8: 10712 | B8: 44924 | C8: Fries | D8: 3.49 | E8: Drive-thru | F8: Gift Card | G8: Walter Muller | H8: 631 | I8: #VALUE! | J8: #VALUE! | K8: 2202.19
A9: 10711 | B9: 44924 | C9: Chicken Sandwiches | D9: 9.95 | E9: Drive-thru | F9: Gift Card | G9: Walter Muller | H9: 282 | I9: #VALUE! | J9: #VALUE! | K9: 2805.9
A10: 10710 | B10: 44924 | C10: Burgers | D10: 12.99 | E10: Drive-thru | F10: Gift Card | G10: Walter Muller | H10: 755 | I10: #VALUE! | J10: #VALUE! | K10: 9807.45
A11: 10709 | B11: 44923 | C11: Sides & Other | D11: 4.99 | E11: Drive-thru | F11: Gift Card | G11: Walter Muller | H11: 201 | I11: #VALUE! | J11: #VALUE! | K11: 1002.99
A12: 10708 | B12: 44923 | C12: Beverages | D12: 2.95 | E12: Drive-thru | F12: Gift Card | G12: Walter Muller | H12: 678 | I12: #VALUE! | J12: #VALUE! | K12: 2000.1
A13: 10707 | B13: 44923 | C13: Fries | D13: 3.49 | E13: Drive-thru | F13: Gift Card | G13: Walter Muller | H13: 631 | I13: #VALUE! | J13: #VALUE! | K13: 2202.19
A14: 10706 | B14: 44923 | C14: Chicken Sandwiches | D14: 9.95 | E14: Drive-thru | F14: Gift Card | G14: Walter Muller | H14: 302 | I14: #VALUE! | J14: #VALUE! | K14: 3004.9
A15: 10705 | B15: 44923 | C15: Burgers | D15: 12.99 | E15: Drive-thru | F15: Gift Card | G15: Walter Muller | H15: 724 | I15: #VALUE! | J15: #VALUE! | K15: 9404.76
... A61: 10608 | B61: 44903 | C61: Beverages | D61: 2.95 | E61: Online | F61: Gift Card | G61: Tom Jackson | H61: 678 | I61: #VALUE! | J61: #VALUE! | K61: 2000.1

Sheet Cards
A3: Sum of Revenue | C3: Count of Order ID | F3: Average of Revenue | I3: Row Labels | J3: Sum of Revenue
A4: 283555.36 | C4: 78 | F4: 3635.3251 | I4: 13-Nov | J4: 45926.19
I5: Grand Total | J5: 45926.19

Sheet Dashboard

Sheet Findings
B2: Select Manager -> | C2: Pablo Perez | J2: Tom Jackson
J3: Pablo Perez
B4: Geography | J4: Joao Silva
B5: Country | C5: =_xlfn.XLOOKUP(C2,Table1[Manager],Table1[Country]) -> #VALUE! | J5: Walter Muller
B6: City | C6: =_xlfn.XLOOKUP(C2,Table1[Manager],Table1[City]) -> #VALUE! | J6: Remy Monet
B8: Revenue
B9: Fries | C9: =SUMIFS(Table1[Revenue],Table1[Product],Findings!B9,Table1[Manager],Findings!$C$2) -> 17219.66
B10: Beverages | C10: =SUMIFS(Table1[Revenue],Table1[Product],Findings!B10,Table1[Manager],Findings!$C$2) -> 18402.1
B11: Sides & Other | C11: =SUMIFS(Table1[Revenue],Table1[Product],Findings!B11,Table1[Manager],Findings!$C$2) -> 9026.91
B12: Burgers | C12: =SUMIFS(Table1[Revenue],Table1[Product],Findings!B12,Table1[Manager],Findings!$C$2) -> 73692.27
B13: Chicken Sandwiches | C13: =SUMIFS(Table1[Revenue],Table1[Product],Findings!B13,Table1[Manager],Findings!$C$2) -> 18089.1
B14: Total | C14: =SUM(C9:C13) -> 136430.04
